[2014-03-17 02:17:13] log.ERROR: exception 'ErrorException' with message 'file_get_contents(): php_network_getaddresses: getaddrinfo failed: Name or service not known' in /media/gedi/projects/thedevs.org/thedevs.org/app/models/All.php:483 Stack trace: #0 [internal function]: Illuminate\Exception\Handler->handleError(2, 'file_get_conten...', '/media/gedi/pro...', 483, Array) #1 /media/gedi/projects/thedevs.org/thedevs.org/app/models/All.php(483): file_get_contents('https://github....') #2 /media/gedi/projects/thedevs.org/thedevs.org/app/routes.php(53): All::getGitStats(Object(User)) #3 [internal function]: {closure}('1') #4 /media/gedi/projects/thedevs.org/thedevs.org/vendor/laravel/framework/src/Illuminate/Routing/Route.php(80): call_user_func_array(Object(Closure), Array) #5 /media/gedi/projects/thedevs.org/thedevs.org/vendor/laravel/framework/src/Illuminate/Routing/Route.php(47): Illuminate\Routing\Route->callCallable() #6 /media/gedi/projects/thedevs.org/thedevs.org/vendor/laravel/framework/src/Illuminate/Routing/Router.php(1016): Illuminate\Routing\Route->run(Object(Illuminate\Http\Request)) #7 /media/gedi/projects/thedevs.org/thedevs.org/vendor/laravel/framework/src/Illuminate/Foundation/Application.php(576): Illuminate\Routing\Router->dispatch(Object(Illuminate\Http\Request)) #8 /media/gedi/projects/thedevs.org/thedevs.org/vendor/laravel/framework/src/Illuminate/Foundation/Application.php(552): Illuminate\Foundation\Application->dispatch(Object(Illuminate\Http\Request)) #9 /media/gedi/projects/thedevs.org/thedevs.org/public/index.php(53): Illuminate\Foundation\Application->run() #10 {main} [] []
[2014-03-17 02:32:30] log.ERROR: exception 'ErrorException' with message 'file_get_contents(): php_network_getaddresses: getaddrinfo failed: Name or service not known' in /media/gedi/projects/thedevs.org/thedevs.org/app/models/All.php:483 Stack trace: #0 [internal function]: Illuminate\Exception\Handler->handleError(2, 'file_get_conten...', '/media/gedi/pro...', 483, Array) #1 /media/gedi/projects/thedevs.org/thedevs.org/app/models/All.php(483): file_get_contents('https://github....') #2 /media/gedi/projects/thedevs.org/thedevs.org/app/routes.php(53): All::getGitStats(Object(User)) #3 [internal function]: {closure}('1') #4 /media/gedi/projects/thedevs.org/thedevs.org/vendor/laravel/framework/src/Illuminate/Routing/Route.php(80): call_user_func_array(Object(Closure), Array) #5 /media/gedi/projects/thedevs.org/thedevs.org/vendor/laravel/framework/src/Illuminate/Routing/Route.php(47): Illuminate\Routing\Route->callCallable() #6 /media/gedi/projects/thedevs.org/thedevs.org/vendor/laravel/framework/src/Illuminate/Routing/Router.php(1016): Illuminate\Routing\Route->run(Object(Illuminate\Http\Request)) #7 /media/gedi/projects/thedevs.org/thedevs.org/vendor/laravel/framework/src/Illuminate/Foundation/Application.php(576): Illuminate\Routing\Router->dispatch(Object(Illuminate\Http\Request)) #8 /media/gedi/projects/thedevs.org/thedevs.org/vendor/laravel/framework/src/Illuminate/Foundation/Application.php(552): Illuminate\Foundation\Application->dispatch(Object(Illuminate\Http\Request)) #9 /media/gedi/projects/thedevs.org/thedevs.org/public/index.php(53): Illuminate\Foundation\Application->run() #10 {main} [] []
[2014-03-17 02:47:41] log.ERROR: exception 'PDOException' with message 'SQLSTATE[42S22]: Column not found: 1054 Unknown column '_token' in 'field list'' in /media/gedi/projects/thedevs.org/thedevs.org/vendor/laravel/framework/src/Illuminate/Database/Connection.php:331 Stack trace: #0 /media/gedi/projects/thedevs.org/thedevs.org/vendor/laravel/framework/src/Illuminate/Database/Connection.php(331): PDO->prepare('insert into `pr...') #1 /media/gedi/projects/thedevs.org/thedevs.org/vendor/laravel/framework/src/Illuminate/Database/Connection.php(521): Illuminate\Database\Connection->Illuminate\Database\{closure}(Object(Illuminate\Database\MySqlConnection), 'insert into `pr...', Array) #2 /media/gedi/projects/thedevs.org/thedevs.org/vendor/laravel/framework/src/Illuminate/Database/Connection.php(332): Illuminate\Database\Connection->run('insert into `pr...', Array, Object(Closure)) #3 /media/gedi/projects/thedevs.org/thedevs.org/vendor/laravel/framework/src/Illuminate/Database/Connection.php(289): Illuminate\Database\Connection->statement('insert into `pr...', Array) #4 /media/gedi/projects/thedevs.org/thedevs.org/vendor/laravel/framework/src/Illuminate/Database/Query/Processors/Processor.php(30): Illuminate\Database\Connection->insert('insert into `pr...', Array) #5 /media/gedi/projects/thedevs.org/thedevs.org/vendor/laravel/framework/src/Illuminate/Database/Query/Builder.php(1444): Illuminate\Database\Query\Processors\Processor->processInsertGetId(Object(Illuminate\Database\Query\Builder), 'insert into `pr...', Array, NULL) #6 [internal function]: Illuminate\Database\Query\Builder->insertGetId(Array) #7 /media/gedi/projects/thedevs.org/thedevs.org/vendor/laravel/framework/src/Illuminate/Database/Eloquent/Builder.php(786): call_user_func_array(Array, Array) #8 [internal function]: Illuminate\Database\Eloquent\Builder->__call('insertGetId', Array) #9 [internal function]: Illuminate\Database\Eloquent\Builder->insertGetId(Array) #10 /media/gedi/projects/thedevs.org/thedevs.org/vendor/laravel/framework/src/Illuminate/Database/Eloquent/Model.php(2653): call_user_func_array(Array, Array) #11 /media/gedi/projects/thedevs.org/thedevs.org/app/controllers/ProjectsController.php(51): Illuminate\Database\Eloquent\Model->__call('insertGetId', Array) #12 /media/gedi/projects/thedevs.org/thedevs.org/app/controllers/ProjectsController.php(51): Project->insertGetId(Array) #13 [internal function]: ProjectsController->store() #14 /media/gedi/projects/thedevs.org/thedevs.org/vendor/laravel/framework/src/Illuminate/Routing/Controllers/Controller.php(138): call_user_func_array(Array, Array) #15 /media/gedi/projects/thedevs.org/thedevs.org/vendor/laravel/framework/src/Illuminate/Routing/Controllers/Controller.php(115): Illuminate\Routing\Controllers\Controller->callMethod('store', Array) #16 /media/gedi/projects/thedevs.org/thedevs.org/vendor/laravel/framework/src/Illuminate/Routing/Router.php(985): Illuminate\Routing\Controllers\Controller->callAction(Object(Illuminate\Foundation\Application), Object(Illuminate\Routing\Router), 'store', Array) #17 [internal function]: Illuminate\Routing\Router->Illuminate\Routing\{closure}() #18 /media/gedi/projects/thedevs.org/thedevs.org/vendor/laravel/framework/src/Illuminate/Routing/Route.php(80): call_user_func_array(Object(Closure), Array) #19 /media/gedi/projects/thedevs.org/thedevs.org/vendor/laravel/framework/src/Illuminate/Routing/Route.php(47): Illuminate\Routing\Route->callCallable() #20 /media/gedi/projects/thedevs.org/thedevs.org/vendor/laravel/framework/src/Illuminate/Routing/Router.php(1016): Illuminate\Routing\Route->run(Object(Illuminate\Http\Request)) #21 /media/gedi/projects/thedevs.org/thedevs.org/vendor/laravel/framework/src/Illuminate/Foundation/Application.php(576): Illuminate\Routing\Router->dispatch(Object(Illuminate\Http\Request)) #22 /media/gedi/projects/thedevs.org/thedevs.org/vendor/laravel/framework/src/Illuminate/Foundation/Application.php(552): Illuminate\Foundation\Application->dispatch(Object(Illuminate\Http\Request)) #23 /media/gedi/projects/thedevs.org/thedevs.org/public/index.php(53): Illuminate\Foundation\Application->run() #24 {main} Next exception 'Exception' with message 'SQLSTATE[42S22]: Column not found: 1054 Unknown column '_token' in 'field list' (SQL: insert into `projects` (`map`, `_token`, `name`, `elevator`, `description`, `type`, `contacts`, `location`, `public`, `creator`, `status`) values (?, ?, ?, ?, ?, ?, ?, ?, ?, ?, ?)) (Bindings: array (   0 => '-12.340001834116316, 56.7333984375',   1 => '4x7sKDhIJ2E1vak8bQhtm4evEaqShPGvKJlBhe0p',   2 => 'saphire1',   3 => 'undefined',   4 => '<p>undefined</p>',   5 => 'undefined',   6 => '<p>undefined</p>',   7 => '',   8 => 'off',   9 => '2',   10 => 'tunuuljgl1jkkshii5qnbt3ij1', ))' in /media/gedi/projects/thedevs.org/thedevs.org/vendor/laravel/framework/src/Illuminate/Database/Connection.php:556 Stack trace: #0 /media/gedi/projects/thedevs.org/thedevs.org/vendor/laravel/framework/src/Illuminate/Database/Connection.php(529): Illuminate\Database\Connection->handleQueryException(Object(PDOException), 'insert into `pr...', Array) #1 /media/gedi/projects/thedevs.org/thedevs.org/vendor/laravel/framework/src/Illuminate/Database/Connection.php(332): Illuminate\Database\Connection->run('insert into `pr...', Array, Object(Closure)) #2 /media/gedi/projects/thedevs.org/thedevs.org/vendor/laravel/framework/src/Illuminate/Database/Connection.php(289): Illuminate\Database\Connection->statement('insert into `pr...', Array) #3 /media/gedi/projects/thedevs.org/thedevs.org/vendor/laravel/framework/src/Illuminate/Database/Query/Processors/Processor.php(30): Illuminate\Database\Connection->insert('insert into `pr...', Array) #4 /media/gedi/projects/thedevs.org/thedevs.org/vendor/laravel/framework/src/Illuminate/Database/Query/Builder.php(1444): Illuminate\Database\Query\Processors\Processor->processInsertGetId(Object(Illuminate\Database\Query\Builder), 'insert into `pr...', Array, NULL) #5 [internal function]: Illuminate\Database\Query\Builder->insertGetId(Array) #6 /media/gedi/projects/thedevs.org/thedevs.org/vendor/laravel/framework/src/Illuminate/Database/Eloquent/Builder.php(786): call_user_func_array(Array, Array) #7 [internal function]: Illuminate\Database\Eloquent\Builder->__call('insertGetId', Array) #8 [internal function]: Illuminate\Database\Eloquent\Builder->insertGetId(Array) #9 /media/gedi/projects/thedevs.org/thedevs.org/vendor/laravel/framework/src/Illuminate/Database/Eloquent/Model.php(2653): call_user_func_array(Array, Array) #10 /media/gedi/projects/thedevs.org/thedevs.org/app/controllers/ProjectsController.php(51): Illuminate\Database\Eloquent\Model->__call('insertGetId', Array) #11 /media/gedi/projects/thedevs.org/thedevs.org/app/controllers/ProjectsController.php(51): Project->insertGetId(Array) #12 [internal function]: ProjectsController->store() #13 /media/gedi/projects/thedevs.org/thedevs.org/vendor/laravel/framework/src/Illuminate/Routing/Controllers/Controller.php(138): call_user_func_array(Array, Array) #14 /media/gedi/projects/thedevs.org/thedevs.org/vendor/laravel/framework/src/Illuminate/Routing/Controllers/Controller.php(115): Illuminate\Routing\Controllers\Controller->callMethod('store', Array) #15 /media/gedi/projects/thedevs.org/thedevs.org/vendor/laravel/framework/src/Illuminate/Routing/Router.php(985): Illuminate\Routing\Controllers\Controller->callAction(Object(Illuminate\Foundation\Application), Object(Illuminate\Routing\Router), 'store', Array) #16 [internal function]: Illuminate\Routing\Router->Illuminate\Routing\{closure}() #17 /media/gedi/projects/thedevs.org/thedevs.org/vendor/laravel/framework/src/Illuminate/Routing/Route.php(80): call_user_func_array(Object(Closure), Array) #18 /media/gedi/projects/thedevs.org/thedevs.org/vendor/laravel/framework/src/Illuminate/Routing/Route.php(47): Illuminate\Routing\Route->callCallable() #19 /media/gedi/projects/thedevs.org/thedevs.org/vendor/laravel/framework/src/Illuminate/Routing/Router.php(1016): Illuminate\Routing\Route->run(Object(Illuminate\Http\Request)) #20 /media/gedi/projects/thedevs.org/thedevs.org/vendor/laravel/framework/src/Illuminate/Foundation/Application.php(576): Illuminate\Routing\Router->dispatch(Object(Illuminate\Http\Request)) #21 /media/gedi/projects/thedevs.org/thedevs.org/vendor/laravel/framework/src/Illuminate/Foundation/Application.php(552): Illuminate\Foundation\Application->dispatch(Object(Illuminate\Http\Request)) #22 /media/gedi/projects/thedevs.org/thedevs.org/public/index.php(53): Illuminate\Foundation\Application->run() #23 {main} [] []
[2014-03-17 03:39:43] log.ERROR: exception 'ErrorException' with message 'file_get_contents(): php_network_getaddresses: getaddrinfo failed: Name or service not known' in /media/gedi/projects/thedevs.org/thedevs.org/app/models/All.php:483 Stack trace: #0 [internal function]: Illuminate\Exception\Handler->handleError(2, 'file_get_conten...', '/media/gedi/pro...', 483, Array) #1 /media/gedi/projects/thedevs.org/thedevs.org/app/models/All.php(483): file_get_contents('https://github....') #2 /media/gedi/projects/thedevs.org/thedevs.org/app/routes.php(53): All::getGitStats(Object(User)) #3 [internal function]: {closure}('1') #4 /media/gedi/projects/thedevs.org/thedevs.org/vendor/laravel/framework/src/Illuminate/Routing/Route.php(80): call_user_func_array(Object(Closure), Array) #5 /media/gedi/projects/thedevs.org/thedevs.org/vendor/laravel/framework/src/Illuminate/Routing/Route.php(47): Illuminate\Routing\Route->callCallable() #6 /media/gedi/projects/thedevs.org/thedevs.org/vendor/laravel/framework/src/Illuminate/Routing/Router.php(1016): Illuminate\Routing\Route->run(Object(Illuminate\Http\Request)) #7 /media/gedi/projects/thedevs.org/thedevs.org/vendor/laravel/framework/src/Illuminate/Foundation/Application.php(576): Illuminate\Routing\Router->dispatch(Object(Illuminate\Http\Request)) #8 /media/gedi/projects/thedevs.org/thedevs.org/vendor/laravel/framework/src/Illuminate/Foundation/Application.php(552): Illuminate\Foundation\Application->dispatch(Object(Illuminate\Http\Request)) #9 /media/gedi/projects/thedevs.org/thedevs.org/public/index.php(53): Illuminate\Foundation\Application->run() #10 {main} [] []
[2014-03-17 03:43:58] log.ERROR: exception 'ErrorException' with message 'file_get_contents(): php_network_getaddresses: getaddrinfo failed: Name or service not known' in /media/gedi/projects/thedevs.org/thedevs.org/app/models/All.php:483 Stack trace: #0 [internal function]: Illuminate\Exception\Handler->handleError(2, 'file_get_conten...', '/media/gedi/pro...', 483, Array) #1 /media/gedi/projects/thedevs.org/thedevs.org/app/models/All.php(483): file_get_contents('https://github....') #2 /media/gedi/projects/thedevs.org/thedevs.org/app/routes.php(53): All::getGitStats(Object(User)) #3 [internal function]: {closure}('1') #4 /media/gedi/projects/thedevs.org/thedevs.org/vendor/laravel/framework/src/Illuminate/Routing/Route.php(80): call_user_func_array(Object(Closure), Array) #5 /media/gedi/projects/thedevs.org/thedevs.org/vendor/laravel/framework/src/Illuminate/Routing/Route.php(47): Illuminate\Routing\Route->callCallable() #6 /media/gedi/projects/thedevs.org/thedevs.org/vendor/laravel/framework/src/Illuminate/Routing/Router.php(1016): Illuminate\Routing\Route->run(Object(Illuminate\Http\Request)) #7 /media/gedi/projects/thedevs.org/thedevs.org/vendor/laravel/framework/src/Illuminate/Foundation/Application.php(576): Illuminate\Routing\Router->dispatch(Object(Illuminate\Http\Request)) #8 /media/gedi/projects/thedevs.org/thedevs.org/vendor/laravel/framework/src/Illuminate/Foundation/Application.php(552): Illuminate\Foundation\Application->dispatch(Object(Illuminate\Http\Request)) #9 /media/gedi/projects/thedevs.org/thedevs.org/public/index.php(53): Illuminate\Foundation\Application->run() #10 {main} [] []
[2014-03-17 03:45:00] log.ERROR: exception 'ErrorException' with message 'file_get_contents(): php_network_getaddresses: getaddrinfo failed: Name or service not known' in /media/gedi/projects/thedevs.org/thedevs.org/app/models/All.php:483 Stack trace: #0 [internal function]: Illuminate\Exception\Handler->handleError(2, 'file_get_conten...', '/media/gedi/pro...', 483, Array) #1 /media/gedi/projects/thedevs.org/thedevs.org/app/models/All.php(483): file_get_contents('https://github....') #2 /media/gedi/projects/thedevs.org/thedevs.org/app/routes.php(53): All::getGitStats(Object(User)) #3 [internal function]: {closure}('1') #4 /media/gedi/projects/thedevs.org/thedevs.org/vendor/laravel/framework/src/Illuminate/Routing/Route.php(80): call_user_func_array(Object(Closure), Array) #5 /media/gedi/projects/thedevs.org/thedevs.org/vendor/laravel/framework/src/Illuminate/Routing/Route.php(47): Illuminate\Routing\Route->callCallable() #6 /media/gedi/projects/thedevs.org/thedevs.org/vendor/laravel/framework/src/Illuminate/Routing/Router.php(1016): Illuminate\Routing\Route->run(Object(Illuminate\Http\Request)) #7 /media/gedi/projects/thedevs.org/thedevs.org/vendor/laravel/framework/src/Illuminate/Foundation/Application.php(576): Illuminate\Routing\Router->dispatch(Object(Illuminate\Http\Request)) #8 /media/gedi/projects/thedevs.org/thedevs.org/vendor/laravel/framework/src/Illuminate/Foundation/Application.php(552): Illuminate\Foundation\Application->dispatch(Object(Illuminate\Http\Request)) #9 /media/gedi/projects/thedevs.org/thedevs.org/public/index.php(53): Illuminate\Foundation\Application->run() #10 {main} [] []
[2014-03-17 04:05:06] log.ERROR: exception 'ErrorException' with message 'Use of undefined constant Date - assumed 'Date'' in /media/gedi/projects/thedevs.org/thedevs.org/app/routes.php:282 Stack trace: #0 /media/gedi/projects/thedevs.org/thedevs.org/app/routes.php(282): Illuminate\Exception\Handler->handleError(8, 'Use of undefine...', '/media/gedi/pro...', 282, Array) #1 [internal function]: {closure}() #2 /media/gedi/projects/thedevs.org/thedevs.org/vendor/laravel/framework/src/Illuminate/Routing/Route.php(80): call_user_func_array(Object(Closure), Array) #3 /media/gedi/projects/thedevs.org/thedevs.org/vendor/laravel/framework/src/Illuminate/Routing/Route.php(47): Illuminate\Routing\Route->callCallable() #4 /media/gedi/projects/thedevs.org/thedevs.org/vendor/laravel/framework/src/Illuminate/Routing/Router.php(1016): Illuminate\Routing\Route->run(Object(Illuminate\Http\Request)) #5 /media/gedi/projects/thedevs.org/thedevs.org/vendor/laravel/framework/src/Illuminate/Foundation/Application.php(576): Illuminate\Routing\Router->dispatch(Object(Illuminate\Http\Request)) #6 /media/gedi/projects/thedevs.org/thedevs.org/vendor/laravel/framework/src/Illuminate/Foundation/Application.php(552): Illuminate\Foundation\Application->dispatch(Object(Illuminate\Http\Request)) #7 /media/gedi/projects/thedevs.org/thedevs.org/public/index.php(53): Illuminate\Foundation\Application->run() #8 {main} [] []
[2014-03-17 04:05:15] log.ERROR: exception 'Symfony\Component\Debug\Exception\FatalErrorException' with message 'Class 'Date' not found' in /media/gedi/projects/thedevs.org/thedevs.org/app/routes.php:282 Stack trace: #0 [internal function]: Illuminate\Exception\Handler->handleShutdown() #1 {main} [] []
[2014-03-17 04:05:22] log.ERROR: exception 'Symfony\Component\Debug\Exception\FatalErrorException' with message 'Class 'Time' not found' in /media/gedi/projects/thedevs.org/thedevs.org/app/routes.php:282 Stack trace: #0 [internal function]: Illuminate\Exception\Handler->handleShutdown() #1 {main} [] []
[2014-03-17 04:05:30] log.ERROR: exception 'Symfony\Component\Debug\Exception\FatalErrorException' with message 'Call to undefined function now()' in /media/gedi/projects/thedevs.org/thedevs.org/app/routes.php:282 Stack trace: #0 [internal function]: Illuminate\Exception\Handler->handleShutdown() #1 {main} [] []
[2014-03-17 04:05:36] log.ERROR: exception 'ErrorException' with message 'Use of undefined constant date - assumed 'date'' in /media/gedi/projects/thedevs.org/thedevs.org/app/routes.php:282 Stack trace: #0 /media/gedi/projects/thedevs.org/thedevs.org/app/routes.php(282): Illuminate\Exception\Handler->handleError(8, 'Use of undefine...', '/media/gedi/pro...', 282, Array) #1 [internal function]: {closure}() #2 /media/gedi/projects/thedevs.org/thedevs.org/vendor/laravel/framework/src/Illuminate/Routing/Route.php(80): call_user_func_array(Object(Closure), Array) #3 /media/gedi/projects/thedevs.org/thedevs.org/vendor/laravel/framework/src/Illuminate/Routing/Route.php(47): Illuminate\Routing\Route->callCallable() #4 /media/gedi/projects/thedevs.org/thedevs.org/vendor/laravel/framework/src/Illuminate/Routing/Router.php(1016): Illuminate\Routing\Route->run(Object(Illuminate\Http\Request)) #5 /media/gedi/projects/thedevs.org/thedevs.org/vendor/laravel/framework/src/Illuminate/Foundation/Application.php(576): Illuminate\Routing\Router->dispatch(Object(Illuminate\Http\Request)) #6 /media/gedi/projects/thedevs.org/thedevs.org/vendor/laravel/framework/src/Illuminate/Foundation/Application.php(552): Illuminate\Foundation\Application->dispatch(Object(Illuminate\Http\Request)) #7 /media/gedi/projects/thedevs.org/thedevs.org/public/index.php(53): Illuminate\Foundation\Application->run() #8 {main} [] []
[2014-03-17 04:06:34] log.ERROR: exception 'ErrorException' with message 'file_get_contents(): php_network_getaddresses: getaddrinfo failed: Name or service not known' in /media/gedi/projects/thedevs.org/thedevs.org/app/models/All.php:483 Stack trace: #0 [internal function]: Illuminate\Exception\Handler->handleError(2, 'file_get_conten...', '/media/gedi/pro...', 483, Array) #1 /media/gedi/projects/thedevs.org/thedevs.org/app/models/All.php(483): file_get_contents('https://github....') #2 /media/gedi/projects/thedevs.org/thedevs.org/app/routes.php(53): All::getGitStats(Object(User)) #3 [internal function]: {closure}('1') #4 /media/gedi/projects/thedevs.org/thedevs.org/vendor/laravel/framework/src/Illuminate/Routing/Route.php(80): call_user_func_array(Object(Closure), Array) #5 /media/gedi/projects/thedevs.org/thedevs.org/vendor/laravel/framework/src/Illuminate/Routing/Route.php(47): Illuminate\Routing\Route->callCallable() #6 /media/gedi/projects/thedevs.org/thedevs.org/vendor/laravel/framework/src/Illuminate/Routing/Router.php(1016): Illuminate\Routing\Route->run(Object(Illuminate\Http\Request)) #7 /media/gedi/projects/thedevs.org/thedevs.org/vendor/laravel/framework/src/Illuminate/Foundation/Application.php(576): Illuminate\Routing\Router->dispatch(Object(Illuminate\Http\Request)) #8 /media/gedi/projects/thedevs.org/thedevs.org/vendor/laravel/framework/src/Illuminate/Foundation/Application.php(552): Illuminate\Foundation\Application->dispatch(Object(Illuminate\Http\Request)) #9 /media/gedi/projects/thedevs.org/thedevs.org/public/index.php(53): Illuminate\Foundation\Application->run() #10 {main} [] []
[2014-03-17 04:13:21] log.ERROR: exception 'Symfony\Component\Debug\Exception\FatalErrorException' with message 'Class 'Carbon' not found' in /media/gedi/projects/thedevs.org/thedevs.org/app/controllers/StoriesController.php:54 Stack trace: #0 [internal function]: Illuminate\Exception\Handler->handleShutdown() #1 {main} [] []
[2014-03-17 04:23:35] log.ERROR: exception 'ErrorException' with message 'file_get_contents(): php_network_getaddresses: getaddrinfo failed: Name or service not known' in /media/gedi/projects/thedevs.org/thedevs.org/app/models/All.php:483 Stack trace: #0 [internal function]: Illuminate\Exception\Handler->handleError(2, 'file_get_conten...', '/media/gedi/pro...', 483, Array) #1 /media/gedi/projects/thedevs.org/thedevs.org/app/models/All.php(483): file_get_contents('https://github....') #2 /media/gedi/projects/thedevs.org/thedevs.org/app/routes.php(53): All::getGitStats(Object(User)) #3 [internal function]: {closure}('1') #4 /media/gedi/projects/thedevs.org/thedevs.org/vendor/laravel/framework/src/Illuminate/Routing/Route.php(80): call_user_func_array(Object(Closure), Array) #5 /media/gedi/projects/thedevs.org/thedevs.org/vendor/laravel/framework/src/Illuminate/Routing/Route.php(47): Illuminate\Routing\Route->callCallable() #6 /media/gedi/projects/thedevs.org/thedevs.org/vendor/laravel/framework/src/Illuminate/Routing/Router.php(1016): Illuminate\Routing\Route->run(Object(Illuminate\Http\Request)) #7 /media/gedi/projects/thedevs.org/thedevs.org/vendor/laravel/framework/src/Illuminate/Foundation/Application.php(576): Illuminate\Routing\Router->dispatch(Object(Illuminate\Http\Request)) #8 /media/gedi/projects/thedevs.org/thedevs.org/vendor/laravel/framework/src/Illuminate/Foundation/Application.php(552): Illuminate\Foundation\Application->dispatch(Object(Illuminate\Http\Request)) #9 /media/gedi/projects/thedevs.org/thedevs.org/public/index.php(53): Illuminate\Foundation\Application->run() #10 {main} [] []
[2014-03-17 05:03:36] log.ERROR: exception 'ErrorException' with message 'file_get_contents(): php_network_getaddresses: getaddrinfo failed: Name or service not known' in /media/gedi/projects/thedevs.org/thedevs.org/app/models/All.php:483 Stack trace: #0 [internal function]: Illuminate\Exception\Handler->handleError(2, 'file_get_conten...', '/media/gedi/pro...', 483, Array) #1 /media/gedi/projects/thedevs.org/thedevs.org/app/models/All.php(483): file_get_contents('https://github....') #2 /media/gedi/projects/thedevs.org/thedevs.org/app/routes.php(53): All::getGitStats(Object(User)) #3 [internal function]: {closure}('1') #4 /media/gedi/projects/thedevs.org/thedevs.org/vendor/laravel/framework/src/Illuminate/Routing/Route.php(80): call_user_func_array(Object(Closure), Array) #5 /media/gedi/projects/thedevs.org/thedevs.org/vendor/laravel/framework/src/Illuminate/Routing/Route.php(47): Illuminate\Routing\Route->callCallable() #6 /media/gedi/projects/thedevs.org/thedevs.org/vendor/laravel/framework/src/Illuminate/Routing/Router.php(1016): Illuminate\Routing\Route->run(Object(Illuminate\Http\Request)) #7 /media/gedi/projects/thedevs.org/thedevs.org/vendor/laravel/framework/src/Illuminate/Foundation/Application.php(576): Illuminate\Routing\Router->dispatch(Object(Illuminate\Http\Request)) #8 /media/gedi/projects/thedevs.org/thedevs.org/vendor/laravel/framework/src/Illuminate/Foundation/Application.php(552): Illuminate\Foundation\Application->dispatch(Object(Illuminate\Http\Request)) #9 /media/gedi/projects/thedevs.org/thedevs.org/public/index.php(53): Illuminate\Foundation\Application->run() #10 {main} [] []
[2014-03-17 05:09:14] log.ERROR: exception 'ErrorException' with message 'file_get_contents(): php_network_getaddresses: getaddrinfo failed: Name or service not known' in /media/gedi/projects/thedevs.org/thedevs.org/app/models/All.php:483 Stack trace: #0 [internal function]: Illuminate\Exception\Handler->handleError(2, 'file_get_conten...', '/media/gedi/pro...', 483, Array) #1 /media/gedi/projects/thedevs.org/thedevs.org/app/models/All.php(483): file_get_contents('https://github....') #2 /media/gedi/projects/thedevs.org/thedevs.org/app/routes.php(53): All::getGitStats(Object(User)) #3 [internal function]: {closure}('1') #4 /media/gedi/projects/thedevs.org/thedevs.org/vendor/laravel/framework/src/Illuminate/Routing/Route.php(80): call_user_func_array(Object(Closure), Array) #5 /media/gedi/projects/thedevs.org/thedevs.org/vendor/laravel/framework/src/Illuminate/Routing/Route.php(47): Illuminate\Routing\Route->callCallable() #6 /media/gedi/projects/thedevs.org/thedevs.org/vendor/laravel/framework/src/Illuminate/Routing/Router.php(1016): Illuminate\Routing\Route->run(Object(Illuminate\Http\Request)) #7 /media/gedi/projects/thedevs.org/thedevs.org/vendor/laravel/framework/src/Illuminate/Foundation/Application.php(576): Illuminate\Routing\Router->dispatch(Object(Illuminate\Http\Request)) #8 /media/gedi/projects/thedevs.org/thedevs.org/vendor/laravel/framework/src/Illuminate/Foundation/Application.php(552): Illuminate\Foundation\Application->dispatch(Object(Illuminate\Http\Request)) #9 /media/gedi/projects/thedevs.org/thedevs.org/public/index.php(53): Illuminate\Foundation\Application->run() #10 {main} [] []
[2014-03-17 07:31:44] log.ERROR: exception 'ErrorException' with message 'file_get_contents(): php_network_getaddresses: getaddrinfo failed: Name or service not known' in /media/gedi/projects/thedevs.org/thedevs.org/app/models/All.php:483 Stack trace: #0 [internal function]: Illuminate\Exception\Handler->handleError(2, 'file_get_conten...', '/media/gedi/pro...', 483, Array) #1 /media/gedi/projects/thedevs.org/thedevs.org/app/models/All.php(483): file_get_contents('https://github....') #2 /media/gedi/projects/thedevs.org/thedevs.org/app/routes.php(53): All::getGitStats(Object(User)) #3 [internal function]: {closure}('1') #4 /media/gedi/projects/thedevs.org/thedevs.org/vendor/laravel/framework/src/Illuminate/Routing/Route.php(80): call_user_func_array(Object(Closure), Array) #5 /media/gedi/projects/thedevs.org/thedevs.org/vendor/laravel/framework/src/Illuminate/Routing/Route.php(47): Illuminate\Routing\Route->callCallable() #6 /media/gedi/projects/thedevs.org/thedevs.org/vendor/laravel/framework/src/Illuminate/Routing/Router.php(1016): Illuminate\Routing\Route->run(Object(Illuminate\Http\Request)) #7 /media/gedi/projects/thedevs.org/thedevs.org/vendor/laravel/framework/src/Illuminate/Foundation/Application.php(576): Illuminate\Routing\Router->dispatch(Object(Illuminate\Http\Request)) #8 /media/gedi/projects/thedevs.org/thedevs.org/vendor/laravel/framework/src/Illuminate/Foundation/Application.php(552): Illuminate\Foundation\Application->dispatch(Object(Illuminate\Http\Request)) #9 /media/gedi/projects/thedevs.org/thedevs.org/public/index.php(53): Illuminate\Foundation\Application->run() #10 {main} [] []
[2014-03-17 07:58:41] log.ERROR: exception 'ErrorException' with message 'file_get_contents(): php_network_getaddresses: getaddrinfo failed: Name or service not known' in /media/gedi/projects/thedevs.org/thedevs.org/app/models/All.php:483 Stack trace: #0 [internal function]: Illuminate\Exception\Handler->handleError(2, 'file_get_conten...', '/media/gedi/pro...', 483, Array) #1 /media/gedi/projects/thedevs.org/thedevs.org/app/models/All.php(483): file_get_contents('https://github....') #2 /media/gedi/projects/thedevs.org/thedevs.org/app/routes.php(53): All::getGitStats(Object(User)) #3 [internal function]: {closure}('1') #4 /media/gedi/projects/thedevs.org/thedevs.org/vendor/laravel/framework/src/Illuminate/Routing/Route.php(80): call_user_func_array(Object(Closure), Array) #5 /media/gedi/projects/thedevs.org/thedevs.org/vendor/laravel/framework/src/Illuminate/Routing/Route.php(47): Illuminate\Routing\Route->callCallable() #6 /media/gedi/projects/thedevs.org/thedevs.org/vendor/laravel/framework/src/Illuminate/Routing/Router.php(1016): Illuminate\Routing\Route->run(Object(Illuminate\Http\Request)) #7 /media/gedi/projects/thedevs.org/thedevs.org/vendor/laravel/framework/src/Illuminate/Foundation/Application.php(576): Illuminate\Routing\Router->dispatch(Object(Illuminate\Http\Request)) #8 /media/gedi/projects/thedevs.org/thedevs.org/vendor/laravel/framework/src/Illuminate/Foundation/Application.php(552): Illuminate\Foundation\Application->dispatch(Object(Illuminate\Http\Request)) #9 /media/gedi/projects/thedevs.org/thedevs.org/public/index.php(53): Illuminate\Foundation\Application->run() #10 {main} [] []
[2014-03-17 08:03:24] log.ERROR: exception 'Illuminate\Database\Eloquent\ModelNotFoundException' in /media/gedi/projects/thedevs.org/thedevs.org/vendor/laravel/framework/src/Illuminate/Database/Eloquent/Model.php:498 Stack trace: #0 /media/gedi/projects/thedevs.org/thedevs.org/app/controllers/StoriesController.php(74): Illuminate\Database\Eloquent\Model::findOrFail('1395043404') #1 [internal function]: StoriesController->show('1395043404') #2 /media/gedi/projects/thedevs.org/thedevs.org/vendor/laravel/framework/src/Illuminate/Routing/Controllers/Controller.php(138): call_user_func_array(Array, Array) #3 /media/gedi/projects/thedevs.org/thedevs.org/vendor/laravel/framework/src/Illuminate/Routing/Controllers/Controller.php(115): Illuminate\Routing\Controllers\Controller->callMethod('show', Array) #4 /media/gedi/projects/thedevs.org/thedevs.org/vendor/laravel/framework/src/Illuminate/Routing/Router.php(985): Illuminate\Routing\Controllers\Controller->callAction(Object(Illuminate\Foundation\Application), Object(Illuminate\Routing\Router), 'show', Array) #5 [internal function]: Illuminate\Routing\Router->Illuminate\Routing\{closure}('1395043404') #6 /media/gedi/projects/thedevs.org/thedevs.org/vendor/laravel/framework/src/Illuminate/Routing/Route.php(80): call_user_func_array(Object(Closure), Array) #7 /media/gedi/projects/thedevs.org/thedevs.org/vendor/laravel/framework/src/Illuminate/Routing/Route.php(47): Illuminate\Routing\Route->callCallable() #8 /media/gedi/projects/thedevs.org/thedevs.org/vendor/laravel/framework/src/Illuminate/Routing/Router.php(1016): Illuminate\Routing\Route->run(Object(Illuminate\Http\Request)) #9 /media/gedi/projects/thedevs.org/thedevs.org/vendor/laravel/framework/src/Illuminate/Foundation/Application.php(576): Illuminate\Routing\Router->dispatch(Object(Illuminate\Http\Request)) #10 /media/gedi/projects/thedevs.org/thedevs.org/vendor/laravel/framework/src/Illuminate/Foundation/Application.php(552): Illuminate\Foundation\Application->dispatch(Object(Illuminate\Http\Request)) #11 /media/gedi/projects/thedevs.org/thedevs.org/public/index.php(53): Illuminate\Foundation\Application->run() #12 {main} [] []
[2014-03-17 08:04:46] log.ERROR: exception 'ErrorException' with message 'file_get_contents(): php_network_getaddresses: getaddrinfo failed: Name or service not known' in /media/gedi/projects/thedevs.org/thedevs.org/app/models/All.php:483 Stack trace: #0 [internal function]: Illuminate\Exception\Handler->handleError(2, 'file_get_conten...', '/media/gedi/pro...', 483, Array) #1 /media/gedi/projects/thedevs.org/thedevs.org/app/models/All.php(483): file_get_contents('https://github....') #2 /media/gedi/projects/thedevs.org/thedevs.org/app/routes.php(53): All::getGitStats(Object(User)) #3 [internal function]: {closure}('1') #4 /media/gedi/projects/thedevs.org/thedevs.org/vendor/laravel/framework/src/Illuminate/Routing/Route.php(80): call_user_func_array(Object(Closure), Array) #5 /media/gedi/projects/thedevs.org/thedevs.org/vendor/laravel/framework/src/Illuminate/Routing/Route.php(47): Illuminate\Routing\Route->callCallable() #6 /media/gedi/projects/thedevs.org/thedevs.org/vendor/laravel/framework/src/Illuminate/Routing/Router.php(1016): Illuminate\Routing\Route->run(Object(Illuminate\Http\Request)) #7 /media/gedi/projects/thedevs.org/thedevs.org/vendor/laravel/framework/src/Illuminate/Foundation/Application.php(576): Illuminate\Routing\Router->dispatch(Object(Illuminate\Http\Request)) #8 /media/gedi/projects/thedevs.org/thedevs.org/vendor/laravel/framework/src/Illuminate/Foundation/Application.php(552): Illuminate\Foundation\Application->dispatch(Object(Illuminate\Http\Request)) #9 /media/gedi/projects/thedevs.org/thedevs.org/public/index.php(53): Illuminate\Foundation\Application->run() #10 {main} [] []
[2014-03-17 08:18:46] log.ERROR: exception 'ErrorException' with message 'file_get_contents(): php_network_getaddresses: getaddrinfo failed: Name or service not known' in /media/gedi/projects/thedevs.org/thedevs.org/app/models/All.php:483 Stack trace: #0 [internal function]: Illuminate\Exception\Handler->handleError(2, 'file_get_conten...', '/media/gedi/pro...', 483, Array) #1 /media/gedi/projects/thedevs.org/thedevs.org/app/models/All.php(483): file_get_contents('https://github....') #2 /media/gedi/projects/thedevs.org/thedevs.org/app/routes.php(53): All::getGitStats(Object(User)) #3 [internal function]: {closure}('1') #4 /media/gedi/projects/thedevs.org/thedevs.org/vendor/laravel/framework/src/Illuminate/Routing/Route.php(80): call_user_func_array(Object(Closure), Array) #5 /media/gedi/projects/thedevs.org/thedevs.org/vendor/laravel/framework/src/Illuminate/Routing/Route.php(47): Illuminate\Routing\Route->callCallable() #6 /media/gedi/projects/thedevs.org/thedevs.org/vendor/laravel/framework/src/Illuminate/Routing/Router.php(1016): Illuminate\Routing\Route->run(Object(Illuminate\Http\Request)) #7 /media/gedi/projects/thedevs.org/thedevs.org/vendor/laravel/framework/src/Illuminate/Foundation/Application.php(576): Illuminate\Routing\Router->dispatch(Object(Illuminate\Http\Request)) #8 /media/gedi/projects/thedevs.org/thedevs.org/vendor/laravel/framework/src/Illuminate/Foundation/Application.php(552): Illuminate\Foundation\Application->dispatch(Object(Illuminate\Http\Request)) #9 /media/gedi/projects/thedevs.org/thedevs.org/public/index.php(53): Illuminate\Foundation\Application->run() #10 {main} [] []
[2014-03-17 08:29:31] log.ERROR: exception 'UnexpectedValueException' with message 'The Response content must be a string or object implementing __toString(), "boolean" given.' in /media/gedi/projects/thedevs.org/thedevs.org/vendor/symfony/http-foundation/Symfony/Component/HttpFoundation/Response.php:358 Stack trace: #0 /media/gedi/projects/thedevs.org/thedevs.org/vendor/laravel/framework/src/Illuminate/Http/Response.php(73): Symfony\Component\HttpFoundation\Response->setContent(false) #1 /media/gedi/projects/thedevs.org/thedevs.org/vendor/symfony/http-foundation/Symfony/Component/HttpFoundation/Response.php(141): Illuminate\Http\Response->setContent(false) #2 /media/gedi/projects/thedevs.org/thedevs.org/vendor/laravel/framework/src/Illuminate/Routing/Router.php(1414): Symfony\Component\HttpFoundation\Response->__construct(false) #3 /media/gedi/projects/thedevs.org/thedevs.org/vendor/laravel/framework/src/Illuminate/Routing/Route.php(58): Illuminate\Routing\Router->prepare(false, Object(Illuminate\Http\Request)) #4 /media/gedi/projects/thedevs.org/thedevs.org/vendor/laravel/framework/src/Illuminate/Routing/Router.php(1016): Illuminate\Routing\Route->run(Object(Illuminate\Http\Request)) #5 /media/gedi/projects/thedevs.org/thedevs.org/vendor/laravel/framework/src/Illuminate/Foundation/Application.php(576): Illuminate\Routing\Router->dispatch(Object(Illuminate\Http\Request)) #6 /media/gedi/projects/thedevs.org/thedevs.org/vendor/laravel/framework/src/Illuminate/Foundation/Application.php(552): Illuminate\Foundation\Application->dispatch(Object(Illuminate\Http\Request)) #7 /media/gedi/projects/thedevs.org/thedevs.org/public/index.php(53): Illuminate\Foundation\Application->run() #8 {main} [] []
[2014-03-17 08:30:21] log.ERROR: exception 'Symfony\Component\Debug\Exception\FatalErrorException' with message 'Call to a member function diffForHumans() on a non-object' in /media/gedi/projects/thedevs.org/thedevs.org/app/routes.php:282 Stack trace: #0 [internal function]: Illuminate\Exception\Handler->handleShutdown() #1 {main} [] []
[2014-03-17 08:36:53] log.ERROR: exception 'Illuminate\Database\Eloquent\ModelNotFoundException' in /media/gedi/projects/thedevs.org/thedevs.org/vendor/laravel/framework/src/Illuminate/Database/Eloquent/Model.php:498 Stack trace: #0 /media/gedi/projects/thedevs.org/thedevs.org/app/controllers/StoriesController.php(75): Illuminate\Database\Eloquent\Model::findOrFail('[object Object]') #1 [internal function]: StoriesController->show('[object Object]') #2 /media/gedi/projects/thedevs.org/thedevs.org/vendor/laravel/framework/src/Illuminate/Routing/Controllers/Controller.php(138): call_user_func_array(Array, Array) #3 /media/gedi/projects/thedevs.org/thedevs.org/vendor/laravel/framework/src/Illuminate/Routing/Controllers/Controller.php(115): Illuminate\Routing\Controllers\Controller->callMethod('show', Array) #4 /media/gedi/projects/thedevs.org/thedevs.org/vendor/laravel/framework/src/Illuminate/Routing/Router.php(985): Illuminate\Routing\Controllers\Controller->callAction(Object(Illuminate\Foundation\Application), Object(Illuminate\Routing\Router), 'show', Array) #5 [internal function]: Illuminate\Routing\Router->Illuminate\Routing\{closure}('[object Object]') #6 /media/gedi/projects/thedevs.org/thedevs.org/vendor/laravel/framework/src/Illuminate/Routing/Route.php(80): call_user_func_array(Object(Closure), Array) #7 /media/gedi/projects/thedevs.org/thedevs.org/vendor/laravel/framework/src/Illuminate/Routing/Route.php(47): Illuminate\Routing\Route->callCallable() #8 /media/gedi/projects/thedevs.org/thedevs.org/vendor/laravel/framework/src/Illuminate/Routing/Router.php(1016): Illuminate\Routing\Route->run(Object(Illuminate\Http\Request)) #9 /media/gedi/projects/thedevs.org/thedevs.org/vendor/laravel/framework/src/Illuminate/Foundation/Application.php(576): Illuminate\Routing\Router->dispatch(Object(Illuminate\Http\Request)) #10 /media/gedi/projects/thedevs.org/thedevs.org/vendor/laravel/framework/src/Illuminate/Foundation/Application.php(552): Illuminate\Foundation\Application->dispatch(Object(Illuminate\Http\Request)) #11 /media/gedi/projects/thedevs.org/thedevs.org/public/index.php(53): Illuminate\Foundation\Application->run() #12 {main} [] []
[2014-03-17 08:37:57] log.ERROR: exception 'ErrorException' with message 'file_get_contents(): php_network_getaddresses: getaddrinfo failed: Name or service not known' in /media/gedi/projects/thedevs.org/thedevs.org/app/models/All.php:483 Stack trace: #0 [internal function]: Illuminate\Exception\Handler->handleError(2, 'file_get_conten...', '/media/gedi/pro...', 483, Array) #1 /media/gedi/projects/thedevs.org/thedevs.org/app/models/All.php(483): file_get_contents('https://github....') #2 /media/gedi/projects/thedevs.org/thedevs.org/app/routes.php(53): All::getGitStats(Object(User)) #3 [internal function]: {closure}('1') #4 /media/gedi/projects/thedevs.org/thedevs.org/vendor/laravel/framework/src/Illuminate/Routing/Route.php(80): call_user_func_array(Object(Closure), Array) #5 /media/gedi/projects/thedevs.org/thedevs.org/vendor/laravel/framework/src/Illuminate/Routing/Route.php(47): Illuminate\Routing\Route->callCallable() #6 /media/gedi/projects/thedevs.org/thedevs.org/vendor/laravel/framework/src/Illuminate/Routing/Router.php(1016): Illuminate\Routing\Route->run(Object(Illuminate\Http\Request)) #7 /media/gedi/projects/thedevs.org/thedevs.org/vendor/laravel/framework/src/Illuminate/Foundation/Application.php(576): Illuminate\Routing\Router->dispatch(Object(Illuminate\Http\Request)) #8 /media/gedi/projects/thedevs.org/thedevs.org/vendor/laravel/framework/src/Illuminate/Foundation/Application.php(552): Illuminate\Foundation\Application->dispatch(Object(Illuminate\Http\Request)) #9 /media/gedi/projects/thedevs.org/thedevs.org/public/index.php(53): Illuminate\Foundation\Application->run() #10 {main} [] []
[2014-03-17 08:49:49] log.ERROR: exception 'ErrorException' with message 'file_get_contents(): php_network_getaddresses: getaddrinfo failed: Name or service not known' in /media/gedi/projects/thedevs.org/thedevs.org/app/models/All.php:483 Stack trace: #0 [internal function]: Illuminate\Exception\Handler->handleError(2, 'file_get_conten...', '/media/gedi/pro...', 483, Array) #1 /media/gedi/projects/thedevs.org/thedevs.org/app/models/All.php(483): file_get_contents('https://github....') #2 /media/gedi/projects/thedevs.org/thedevs.org/app/routes.php(53): All::getGitStats(Object(User)) #3 [internal function]: {closure}('1') #4 /media/gedi/projects/thedevs.org/thedevs.org/vendor/laravel/framework/src/Illuminate/Routing/Route.php(80): call_user_func_array(Object(Closure), Array) #5 /media/gedi/projects/thedevs.org/thedevs.org/vendor/laravel/framework/src/Illuminate/Routing/Route.php(47): Illuminate\Routing\Route->callCallable() #6 /media/gedi/projects/thedevs.org/thedevs.org/vendor/laravel/framework/src/Illuminate/Routing/Router.php(1016): Illuminate\Routing\Route->run(Object(Illuminate\Http\Request)) #7 /media/gedi/projects/thedevs.org/thedevs.org/vendor/laravel/framework/src/Illuminate/Foundation/Application.php(576): Illuminate\Routing\Router->dispatch(Object(Illuminate\Http\Request)) #8 /media/gedi/projects/thedevs.org/thedevs.org/vendor/laravel/framework/src/Illuminate/Foundation/Application.php(552): Illuminate\Foundation\Application->dispatch(Object(Illuminate\Http\Request)) #9 /media/gedi/projects/thedevs.org/thedevs.org/public/index.php(53): Illuminate\Foundation\Application->run() #10 {main} [] []
[2014-03-17 08:59:52] log.ERROR: exception 'ErrorException' with message 'file_get_contents(): php_network_getaddresses: getaddrinfo failed: Name or service not known' in /media/gedi/projects/thedevs.org/thedevs.org/app/models/All.php:483 Stack trace: #0 [internal function]: Illuminate\Exception\Handler->handleError(2, 'file_get_conten...', '/media/gedi/pro...', 483, Array) #1 /media/gedi/projects/thedevs.org/thedevs.org/app/models/All.php(483): file_get_contents('https://github....') #2 /media/gedi/projects/thedevs.org/thedevs.org/app/routes.php(53): All::getGitStats(Object(User)) #3 [internal function]: {closure}('1') #4 /media/gedi/projects/thedevs.org/thedevs.org/vendor/laravel/framework/src/Illuminate/Routing/Route.php(80): call_user_func_array(Object(Closure), Array) #5 /media/gedi/projects/thedevs.org/thedevs.org/vendor/laravel/framework/src/Illuminate/Routing/Route.php(47): Illuminate\Routing\Route->callCallable() #6 /media/gedi/projects/thedevs.org/thedevs.org/vendor/laravel/framework/src/Illuminate/Routing/Router.php(1016): Illuminate\Routing\Route->run(Object(Illuminate\Http\Request)) #7 /media/gedi/projects/thedevs.org/thedevs.org/vendor/laravel/framework/src/Illuminate/Foundation/Application.php(576): Illuminate\Routing\Router->dispatch(Object(Illuminate\Http\Request)) #8 /media/gedi/projects/thedevs.org/thedevs.org/vendor/laravel/framework/src/Illuminate/Foundation/Application.php(552): Illuminate\Foundation\Application->dispatch(Object(Illuminate\Http\Request)) #9 /media/gedi/projects/thedevs.org/thedevs.org/public/index.php(53): Illuminate\Foundation\Application->run() #10 {main} [] []
[2014-03-17 09:19:39] log.ERROR: exception 'InvalidArgumentException' with message 'Trailing data' in /media/gedi/projects/thedevs.org/thedevs.org/vendor/nesbot/carbon/src/Carbon/Carbon.php:358 Stack trace: #0 /media/gedi/projects/thedevs.org/thedevs.org/vendor/laravel/framework/src/Illuminate/Database/Eloquent/Model.php(2237): Carbon\Carbon::createFromFormat('Y-m-d H:i:s', '0000-11-00 00:0...') #1 /media/gedi/projects/thedevs.org/thedevs.org/vendor/laravel/framework/src/Illuminate/Database/Eloquent/Model.php(2168): Illuminate\Database\Eloquent\Model->fromDateTime('0000-11-00 00:0...') #2 /media/gedi/projects/thedevs.org/thedevs.org/vendor/laravel/framework/src/Illuminate/Database/Eloquent/Model.php(306): Illuminate\Database\Eloquent\Model->setAttribute('created_at', '0000-11-00 00:0...') #3 /media/gedi/projects/thedevs.org/thedevs.org/vendor/laravel/framework/src/Illuminate/Database/Eloquent/Model.php(237): Illuminate\Database\Eloquent\Model->fill(Array) #4 /media/gedi/projects/thedevs.org/thedevs.org/vendor/laravel/framework/src/Illuminate/Database/Eloquent/Model.php(375): Illuminate\Database\Eloquent\Model->__construct(Array) #5 /media/gedi/projects/thedevs.org/thedevs.org/app/controllers/StoriesController.php(55): Illuminate\Database\Eloquent\Model::create(Array) #6 [internal function]: StoriesController->store() #7 /media/gedi/projects/thedevs.org/thedevs.org/vendor/laravel/framework/src/Illuminate/Routing/Controllers/Controller.php(138): call_user_func_array(Array, Array) #8 /media/gedi/projects/thedevs.org/thedevs.org/vendor/laravel/framework/src/Illuminate/Routing/Controllers/Controller.php(115): Illuminate\Routing\Controllers\Controller->callMethod('store', Array) #9 /media/gedi/projects/thedevs.org/thedevs.org/vendor/laravel/framework/src/Illuminate/Routing/Router.php(985): Illuminate\Routing\Controllers\Controller->callAction(Object(Illuminate\Foundation\Application), Object(Illuminate\Routing\Router), 'store', Array) #10 [internal function]: Illuminate\Routing\Router->Illuminate\Routing\{closure}() #11 /media/gedi/projects/thedevs.org/thedevs.org/vendor/laravel/framework/src/Illuminate/Routing/Route.php(80): call_user_func_array(Object(Closure), Array) #12 /media/gedi/projects/thedevs.org/thedevs.org/vendor/laravel/framework/src/Illuminate/Routing/Route.php(47): Illuminate\Routing\Route->callCallable() #13 /media/gedi/projects/thedevs.org/thedevs.org/vendor/laravel/framework/src/Illuminate/Routing/Router.php(1016): Illuminate\Routing\Route->run(Object(Illuminate\Http\Request)) #14 /media/gedi/projects/thedevs.org/thedevs.org/vendor/laravel/framework/src/Illuminate/Foundation/Application.php(576): Illuminate\Routing\Router->dispatch(Object(Illuminate\Http\Request)) #15 /media/gedi/projects/thedevs.org/thedevs.org/vendor/laravel/framework/src/Illuminate/Foundation/Application.php(552): Illuminate\Foundation\Application->dispatch(Object(Illuminate\Http\Request)) #16 /media/gedi/projects/thedevs.org/thedevs.org/public/index.php(53): Illuminate\Foundation\Application->run() #17 {main} [] []
[2014-03-17 09:27:45] log.ERROR: exception 'ErrorException' with message 'file_get_contents(): php_network_getaddresses: getaddrinfo failed: Name or service not known' in /media/gedi/projects/thedevs.org/thedevs.org/app/models/All.php:483 Stack trace: #0 [internal function]: Illuminate\Exception\Handler->handleError(2, 'file_get_conten...', '/media/gedi/pro...', 483, Array) #1 /media/gedi/projects/thedevs.org/thedevs.org/app/models/All.php(483): file_get_contents('https://github....') #2 /media/gedi/projects/thedevs.org/thedevs.org/app/routes.php(53): All::getGitStats(Object(User)) #3 [internal function]: {closure}('1') #4 /media/gedi/projects/thedevs.org/thedevs.org/vendor/laravel/framework/src/Illuminate/Routing/Route.php(80): call_user_func_array(Object(Closure), Array) #5 /media/gedi/projects/thedevs.org/thedevs.org/vendor/laravel/framework/src/Illuminate/Routing/Route.php(47): Illuminate\Routing\Route->callCallable() #6 /media/gedi/projects/thedevs.org/thedevs.org/vendor/laravel/framework/src/Illuminate/Routing/Router.php(1016): Illuminate\Routing\Route->run(Object(Illuminate\Http\Request)) #7 /media/gedi/projects/thedevs.org/thedevs.org/vendor/laravel/framework/src/Illuminate/Foundation/Application.php(576): Illuminate\Routing\Router->dispatch(Object(Illuminate\Http\Request)) #8 /media/gedi/projects/thedevs.org/thedevs.org/vendor/laravel/framework/src/Illuminate/Foundation/Application.php(552): Illuminate\Foundation\Application->dispatch(Object(Illuminate\Http\Request)) #9 /media/gedi/projects/thedevs.org/thedevs.org/public/index.php(53): Illuminate\Foundation\Application->run() #10 {main} [] []
[2014-03-17 09:29:05] log.ERROR: exception 'ErrorException' with message 'file_get_contents(): php_network_getaddresses: getaddrinfo failed: Name or service not known' in /media/gedi/projects/thedevs.org/thedevs.org/app/models/All.php:483 Stack trace: #0 [internal function]: Illuminate\Exception\Handler->handleError(2, 'file_get_conten...', '/media/gedi/pro...', 483, Array) #1 /media/gedi/projects/thedevs.org/thedevs.org/app/models/All.php(483): file_get_contents('https://github....') #2 /media/gedi/projects/thedevs.org/thedevs.org/app/routes.php(53): All::getGitStats(Object(User)) #3 [internal function]: {closure}('1') #4 /media/gedi/projects/thedevs.org/thedevs.org/vendor/laravel/framework/src/Illuminate/Routing/Route.php(80): call_user_func_array(Object(Closure), Array) #5 /media/gedi/projects/thedevs.org/thedevs.org/vendor/laravel/framework/src/Illuminate/Routing/Route.php(47): Illuminate\Routing\Route->callCallable() #6 /media/gedi/projects/thedevs.org/thedevs.org/vendor/laravel/framework/src/Illuminate/Routing/Router.php(1016): Illuminate\Routing\Route->run(Object(Illuminate\Http\Request)) #7 /media/gedi/projects/thedevs.org/thedevs.org/vendor/laravel/framework/src/Illuminate/Foundation/Application.php(576): Illuminate\Routing\Router->dispatch(Object(Illuminate\Http\Request)) #8 /media/gedi/projects/thedevs.org/thedevs.org/vendor/laravel/framework/src/Illuminate/Foundation/Application.php(552): Illuminate\Foundation\Application->dispatch(Object(Illuminate\Http\Request)) #9 /media/gedi/projects/thedevs.org/thedevs.org/public/index.php(53): Illuminate\Foundation\Application->run() #10 {main} [] []
[2014-03-17 18:57:10] log.ERROR: exception 'ErrorException' with message 'file_get_contents(): php_network_getaddresses: getaddrinfo failed: Name or service not known' in /media/gedi/projects/thedevs.org/thedevs.org/app/models/All.php:483 Stack trace: #0 [internal function]: Illuminate\Exception\Handler->handleError(2, 'file_get_conten...', '/media/gedi/pro...', 483, Array) #1 /media/gedi/projects/thedevs.org/thedevs.org/app/models/All.php(483): file_get_contents('https://github....') #2 /media/gedi/projects/thedevs.org/thedevs.org/app/routes.php(53): All::getGitStats(Object(User)) #3 [internal function]: {closure}('1') #4 /media/gedi/projects/thedevs.org/thedevs.org/vendor/laravel/framework/src/Illuminate/Routing/Route.php(80): call_user_func_array(Object(Closure), Array) #5 /media/gedi/projects/thedevs.org/thedevs.org/vendor/laravel/framework/src/Illuminate/Routing/Route.php(47): Illuminate\Routing\Route->callCallable() #6 /media/gedi/projects/thedevs.org/thedevs.org/vendor/laravel/framework/src/Illuminate/Routing/Router.php(1016): Illuminate\Routing\Route->run(Object(Illuminate\Http\Request)) #7 /media/gedi/projects/thedevs.org/thedevs.org/vendor/laravel/framework/src/Illuminate/Foundation/Application.php(576): Illuminate\Routing\Router->dispatch(Object(Illuminate\Http\Request)) #8 /media/gedi/projects/thedevs.org/thedevs.org/vendor/laravel/framework/src/Illuminate/Foundation/Application.php(552): Illuminate\Foundation\Application->dispatch(Object(Illuminate\Http\Request)) #9 /media/gedi/projects/thedevs.org/thedevs.org/public/index.php(53): Illuminate\Foundation\Application->run() #10 {main} [] []
[2014-03-17 18:57:21] log.ERROR: exception 'ErrorException' with message 'file_get_contents(): php_network_getaddresses: getaddrinfo failed: Name or service not known' in /media/gedi/projects/thedevs.org/thedevs.org/app/models/All.php:483 Stack trace: #0 [internal function]: Illuminate\Exception\Handler->handleError(2, 'file_get_conten...', '/media/gedi/pro...', 483, Array) #1 /media/gedi/projects/thedevs.org/thedevs.org/app/models/All.php(483): file_get_contents('https://github....') #2 /media/gedi/projects/thedevs.org/thedevs.org/app/routes.php(53): All::getGitStats(Object(User)) #3 [internal function]: {closure}('1') #4 /media/gedi/projects/thedevs.org/thedevs.org/vendor/laravel/framework/src/Illuminate/Routing/Route.php(80): call_user_func_array(Object(Closure), Array) #5 /media/gedi/projects/thedevs.org/thedevs.org/vendor/laravel/framework/src/Illuminate/Routing/Route.php(47): Illuminate\Routing\Route->callCallable() #6 /media/gedi/projects/thedevs.org/thedevs.org/vendor/laravel/framework/src/Illuminate/Routing/Router.php(1016): Illuminate\Routing\Route->run(Object(Illuminate\Http\Request)) #7 /media/gedi/projects/thedevs.org/thedevs.org/vendor/laravel/framework/src/Illuminate/Foundation/Application.php(576): Illuminate\Routing\Router->dispatch(Object(Illuminate\Http\Request)) #8 /media/gedi/projects/thedevs.org/thedevs.org/vendor/laravel/framework/src/Illuminate/Foundation/Application.php(552): Illuminate\Foundation\Application->dispatch(Object(Illuminate\Http\Request)) #9 /media/gedi/projects/thedevs.org/thedevs.org/public/index.php(53): Illuminate\Foundation\Application->run() #10 {main} [] []
[2014-03-17 19:00:09] log.ERROR: exception 'ErrorException' with message 'file_get_contents(): Filename cannot be empty' in /media/gedi/projects/thedevs.org/thedevs.org/app/models/All.php:483 Stack trace: #0 [internal function]: Illuminate\Exception\Handler->handleError(2, 'file_get_conten...', '/media/gedi/pro...', 483, Array) #1 /media/gedi/projects/thedevs.org/thedevs.org/app/models/All.php(483): file_get_contents('') #2 /media/gedi/projects/thedevs.org/thedevs.org/app/routes.php(53): All::getGitStats(Object(User)) #3 [internal function]: {closure}('4') #4 /media/gedi/projects/thedevs.org/thedevs.org/vendor/laravel/framework/src/Illuminate/Routing/Route.php(80): call_user_func_array(Object(Closure), Array) #5 /media/gedi/projects/thedevs.org/thedevs.org/vendor/laravel/framework/src/Illuminate/Routing/Route.php(47): Illuminate\Routing\Route->callCallable() #6 /media/gedi/projects/thedevs.org/thedevs.org/vendor/laravel/framework/src/Illuminate/Routing/Router.php(1016): Illuminate\Routing\Route->run(Object(Illuminate\Http\Request)) #7 /media/gedi/projects/thedevs.org/thedevs.org/vendor/laravel/framework/src/Illuminate/Foundation/Application.php(576): Illuminate\Routing\Router->dispatch(Object(Illuminate\Http\Request)) #8 /media/gedi/projects/thedevs.org/thedevs.org/vendor/laravel/framework/src/Illuminate/Foundation/Application.php(552): Illuminate\Foundation\Application->dispatch(Object(Illuminate\Http\Request)) #9 /media/gedi/projects/thedevs.org/thedevs.org/public/index.php(53): Illuminate\Foundation\Application->run() #10 {main} [] []
